Workbook

Sheet Project info summary
A1: RBSX Group Ltd Financial Investment and User Managment System
A2: Key Project Info
A3: Intended start Date | B3: 45199
A4: Requested time scale (Weeks) | B4: 17
A5: Requested time scale (Days) | B5: =B4*7 -> 119
A6: Hours worked per day per Staff member | B6: 7
A7: Predicted staff Absence (Days) | B7: 0
A9: Task | B9: Estimated number of work hours | D9: Staff member | E9: Role | F9: Key | G9: Pay per hour
A10: Upgrade infrastructure | B10: 21 | D10: Sarah O’Toole | E10: Senior Software Engineer | G10: 105
A11: Install physical server | B11: 7 | D11: Ahad Shafiq | E11: Junior Software Engineer | G11: 25
A12: Develop Module - Investments and savings | B12: 115 | D12: Terry Duran | E12: Junior Software Engineer | G12: 45
A13: Develop Module - User interface | B13: 70 | D13: Gina Diaz | E13: Database Engineer | G13: 47.5
A14: Develop Module - Information feed | B14: 126 | D14: Marius Bronski | E14: Network Engineer | G14: 73
A15: Develop Module - Back-end database | B15: 147
A16: Develop Module - Data analytics | B16: 112
A17: Develop Module – Communications | B17: 105
A18: Deploy Modules | B18: 7
B19: (per module)
A20: Unit testing | B20: 21
B21: (per module)
A22: Integration testing | B22: 14
B23: (per module)
A24: Fixing and regression testing for major fault | B24: 14
B25: (per fault found)
A26: Fixing and regression testing for minor fault | B26: 7
B27: (per fault found)
A28: User/acceptance testing | B28: 35
A29: Create a Test plan | B29: 14
A30: User Training | B30: 21

Sheet Gannt
E2: 1 | F2: 2 | G2: 3 | H2: 4 | I2: 5 | J2: 6 | K2: 7 | L2: 8 | M2: 9 | N2: 10 | O2: 11 | P2: 12 | Q2: 13 | R2: 14 | S2: 15 | T2: 16 | U2: 17 | V2: 18 | W2: 19 | X2: 20 | Y2: 21 | Z2: 22 | AA2: 23 | AB2: 24 | AC2: 25 | AD2: 26 | AE2: 27 | AF2: 28 | AG2: 29 | AH2: 30 | AI2: 31 | AJ2: 32 | AK2: 33 | AL2: 34 | AM2: 35 | AN2: 36 | AO2: 37 | AP2: 38 | AQ2: 39 | AR2: 40 | AS2: 41 | AT2: 42 | AU2: 43 | AV2: 44 | AW2: 45 | AX2: 46 | AY2: 47 | AZ2: 48 | BA2: 49 | BB2: 50 | BC2: 51 | BD2: 52 | BE2: 53 | BF2: 54 | BG2: 55 | BH2: 56 | BI2: 57 | BJ2: 58 | BK2: 59 | BL2: 60 | BM2: 61 | BN2: 62 | BO2: 63 | BP2: 64 | BQ2: 65 | BR2: 66 | BS2: 67 | BT2: 68 | BU2: 69 | BV2: 70 | BW2: 71 | BX2: 72 | BY2: 73 | BZ2: 74 | CA2: 75 | CB2: 76 | CC2: 77 | CD2: 78 | CE2: 79 | CF2: 80 | CG2: 81 | CH2: 82 | CI2: 83 | CJ2: 84 | CK2: 85 | CL2: 86 | CM2: 87 | CN2: 88 | CO2: 89 | CP2: 90 | CQ2: 91 | CR2: 92 | CS2: 93 | CT2: 94 | CU2: 95 | CV2: 96 | CW2: 97 | CX2: 98 | CY2: 99 | CZ2: 100 | DA2: 101 | DB2: 102 | DC2: 103 | DD2: 104 | DE2: 105 | DF2: 106 | DG2: 107 | DH2: 108 | DI2: 109 | DJ2: 110 | DK2: 111 | DL2: 112 | DM2: 113 | DN2: 114 | DO2: 115 | DP2: 116 | DQ2: 117 | DR2: 118 | DS2: 119 | DT2: 120 | DU2: 121 | DV2: 122 | DW2: 123 | DX2: 124 | DY2: 125 | DZ2: 126 | EA2: 127 | EB2: 128 | EC2: 129 | ED2: 130 | EE2: 131 | EF2: 132 | EG2: 133 | EH2: 134 | EI2: 135 | EJ2: 136 | EK2: 137 | EL2: 138 | EM2: 139 | EN2: 140 | EO2: 141 | EP2: 142 | EQ2: 143 | ER2: 144 | ES2: 145 | ET2: 146 | EU2: 147 | EV2: 148 | EW2: 149 | EX2: 150 | EY2: 151 | EZ2: 152 | FA2: 153 | FB2: 154 | FC2: 155 | FD2: 156
E3: Monday | F3: Tuesday | G3: Wednesday | H3: Thursday | I3: Friday | J3: Saturday | K3: Sunday | L3: Monday | M3: Tuesday | N3: Wednesday | O3: Thursday | P3: Friday | Q3: Saturday | R3: Sunday | S3: Monday | T3: Tuesday | U3: Wednesday | V3: Thursday | W3: Friday | X3: Saturday | Y3: Sunday | Z3: Monday | AA3: Tuesday | AB3: Wednesday | AC3: Thursday | AD3: Friday | AE3: Saturday | AF3: Sunday | AG3: Monday | AH3: Tuesday | AI3: Wednesday | AJ3: Thursday | AK3: Friday | AL3: Saturday | AM3: Sunday | AN3: Monday | AO3: Tuesday | AP3: Wednesday | AQ3: Thursday | AR3: Friday | AS3: Saturday | AT3: Sunday | AU3: Monday | AV3: Tuesday | AW3: Wednesday | AX3: Thursday | AY3: Friday | AZ3: Saturday | BA3: Sunday | BB3: Monday | BC3: Tuesday | BD3: Wednesday | BE3: Thursday | BF3: Friday | BG3: Saturday | BH3: Sunday | BI3: Monday | BJ3: Tuesday | BK3: Wednesday | BL3: Thursday | BM3: Friday | BN3: Saturday | BO3: Sunday | BP3: Monday | BQ3: Tuesday | BR3: Wednesday | BS3: Thursday | BT3: Friday | BU3: Saturday | BV3: Sunday | BW3: Monday | BX3: Tuesday | BY3: Wednesday | BZ3: Thursday | CA3: Friday | CB3: Saturday | CC3: Sunday | CD3: Monday | CE3: Tuesday | CF3: Wednesday | CG3: Thursday | CH3: Friday | CI3: Saturday | CJ3: Sunday | CK3: Monday | CL3: Tuesday | CM3: Wednesday | CN3: Thursday | CO3: Friday | CP3: Saturday | CQ3: Sunday | CR3: Monday | CS3: Tuesday | CT3: Wednesday | CU3: Thursday | CV3: Friday | CW3: Saturday | CX3: Sunday | CY3: Monday | CZ3: Tuesday | DA3: Wednesday | DB3: Thursday | DC3: Friday | DD3: Saturday | DE3: Sunday | DF3: Monday | DG3: Tuesday | DH3: Wednesday | DI3: Thursday | DJ3: Friday | DK3: Saturday | DL3: Sunday | DM3: Monday | DN3: Tuesday | DO3: Wednesday | DP3: Thursday | DQ3: Friday | DR3: Saturday | DS3: Sunday | DT3: Monday | DU3: Tuesday | DV3: Wednesday | DW3: Thursday | DX3: Friday | DY3: Saturday | DZ3: Sunday | EA3: Monday | EB3: Tuesday | EC3: Wednesday | ED3: Thursday | EE3: Friday | EF3: Saturday | EG3: Sunday | EH3: Monday | EI3: Tuesday | EJ3: Wednesday | EK3: Thursday | EL3: Friday | EM3: Saturday | EN3: Sunday | EO3: Monday | EP3: Tuesday | EQ3: Wednesday | ER3: Thursday | ES3: Friday | ET3: Saturday | EU3: Sunday | EV3: Monday | EW3: Tuesday | EX3: Wednesday | EY3: Thursday | EZ3: Friday | FA3: Saturday | FB3: Sunday | FC3: Monday | FD3: Tuesday
E4: 45565 | F4: 45566 | G4: 45567 | H4: 45568 | I4: 45569 | J4: 45570 | K4: 45571 | L4: 45572 | M4: 45573 | N4: 45574 | O4: 45575 | P4: 45576 | Q4: 45577 | R4: 45578 | S4: 45579 | T4: 45580 | U4: 45581 | V4: 45582 | W4: 45583 | X4: 45584 | Y4: 45585 | Z4: 45586 | AA4: 45587 | AB4: 45588 | AC4: 45589 | AD4: 45590 | AE4: 45591 | AF4: 45592 | AG4: 45593 | AH4: 45594 | AI4: 45595 | AJ4: 45596 | AK4: 45597 | AL4: 45598 | AM4: 45599 | AN4: 45600 | AO4: 45601 | AP4: 45602 | AQ4: 45603 | AR4: 45604 | AS4: 45605 | AT4: 45606 | AU4: 45607 | AV4: 45608 | AW4: 45609 | AX4: 45610 | AY4: 45611 | AZ4: 45612 | BA4: 45613 | BB4: 45614 | BC4: 45615 | BD4: 45616 | BE4: 45617 | BF4: 45618 | BG4: 45619 | BH4: 45620 | BI4: 45621 | BJ4: 45622 | BK4: 45623 | BL4: 45624 | BM4: 45625 | BN4: 45626 | BO4: 45627 | BP4: 45628 | BQ4: 45629 | BR4: 45630 | BS4: 45631 | BT4: 45632 | BU4: 45633 | BV4: 45634 | BW4: 45635 | BX4: 45636 | BY4: 45637 | BZ4: 45638 | CA4: 45639 | CB4: 45640 | CC4: 45641 | CD4: 45642 | CE4: 45643 | CF4: 45644 | CG4: 45645 | CH4: 45646 | CI4: 45647 | CJ4: 45648 | CK4: 45649 | CL4: 45650 | CM4: 45651 | CN4: 45652 | CO4: 45653 | CP4: 45654 | CQ4: 45655 | CR4: 45656 | CS4: 45657 | CT4: 45658 | CU4: 45659 | CV4: 45660 | CW4: 45661 | CX4: 45662 | CY4: 45663 | CZ4: 45664 | DA4: 45665 | DB4: 45666 | DC4: 45667 | DD4: 45668 | DE4: 45669 | DF4: 45670 | DG4: 45671 | DH4: 45672 | DI4: 45673 | DJ4: 45674 | DK4: 45675 | DL4: 45676 | DM4: 45677 | DN4: 45678 | DO4: 45679 | DP4: 45680 | DQ4: 45681 | DR4: 45682 | DS4: 45683 | DT4: 45684 | DU4: 45685 | DV4: 45686 | DW4: 45687 | DX4: 45688 | DY4: 45689 | DZ4: 45690 | EA4: 45691 | EB4: 45692 | EC4: 45693 | ED4: 45694 | EE4: 45695 | EF4: 45696 | EG4: 45697 | EH4: 45698 | EI4: 45699 | EJ4: 45700 | EK4: 45701 | EL4: 45702 | EM4: 45703 | EN4: 45704 | EO4: 45705 | EP4: 45706 | EQ4: 45707 | ER4: 45708 | ES4: 45709 | ET4: 45710 | EU4: 45711 | EV4: 45712 | EW4: 45713 | EX4: 45714 | EY4: 45715 | EZ4: 45716 | FA4: 45717 | FB4: 45718 | FC4: 45719 | FD4: 45720
A5: Task | B5: Sub Task/Notes | C5: Staff assigned | D5: Total hours assigned to task | DS5: Target completion date
A6: Upgrade infrastructure | C6: Marius Bronski | D6: =SUM(E6:EI6) -> 21 | E6: 7 | F6: 7 | G6: 7
A7: Install physical server | B7: Cloud server chosen – contingency time | C7: Marius Bronski | D7: =SUM(E7:EI7) -> 7 | H7: 7
A8: Develop Module - Back-end database | B8: Phase 1 | C8: Gina Diaz | D8: =SUM(E8:EI8) -> 49 | E8: 7 | F8: 7 | G8: 7 | H8: 7 | I8: 7 | L8: 7 | M8: 7
A9: Unit testing | B9: Test phase 1 | C9: Gina Diaz | D9: =SUM(E9:EI9) -> 7 | N9: 7
A10: Fixing and regression testing for minor fault | B10: Database minor fault 1 | C10: Gina Diaz | D10: =SUM(E10:EI10) -> 7 | O10: 7
A11: Develop Module - Back-end database | B11: Phase 2 | C11: Gina Diaz | D11: =SUM(E11:EI11) -> 49 | P11: 7 | S11: 7 | T11: 7 | U11: 7 | V11: 7 | W11: 7 | Z11: 7
A12: Unit testing | B12: Test phase 2 | C12: Gina Diaz | D12: =SUM(E12:EI12) -> 7 | AA12: 7
A13: Fixing and regression testing for minor fault | B13: Database minor fault 2 | C13: Gina Diaz | D13: =SUM(E13:EI13) -> 7 | AB13: 7
A14: Develop Module - Back-end database | B14: Phase 3 | C14: Gina Diaz | D14: =SUM(E14:EI14) -> 49 | AC14: 7 | AD14: 7 | AG14: 7 | AH14: 7 | AI14: 7 | AJ14: 7 | AK14: 7
A15: Unit testing | B15: Test phase 3 | C15: Gina Diaz | D15: =SUM(E15:EI15) -> 7 | AN15: 7
A16: Fixing and regression testing for minor fault | B16: Database minor fault 3 | C16: Gina Diaz | D16: =SUM(E16:EI16) -> 7 | AO16: 7
A17: Develop Module - Investments and savings | B17: Phase 1 | C17: Sarah O’Toole | D17: =SUM(E17:EI17) -> 35 | E17: 7 | F17: 7 | G17: 7 | H17: 7 | I17: 7
A18: Unit testing | B18: Test Phase 1 | C18: Sarah O’Toole | D18: =SUM(E18:EI18) -> 7 | L18: 7
A19: Fixing and regression testing for minor fault | B19: Investments minor fault 1 | C19: Sarah O’Toole | D19: =SUM(E19:EI19) -> 7 | M19: 7
A20: Develop Module - Investments and savings | B20: Phase 2 | C20: Sarah O’Toole | D20: =SUM(E20:EI20) -> 42 | N20: 7 | O20: 7 | P20: 7 | S20: 7 | T20: 7 | U20: 7
A21: Unit testing | B21: Test Phase 2 | C21: Sarah O’Toole | D21: =SUM(E21:EI21) -> 7 | V21: 7
A22: Fixing and regression testing for minor fault | B22: Investments minor fault 2 | C22: Sarah O’Toole | D22: =SUM(E22:EI22) -> 7 | W22: 7
A23: Develop Module - Investments and savings | B23: Phase 3 | C23: Sarah O’Toole | D23: =SUM(E23:EI23) -> 42 | Z23: 7 | AA23: 7 | AB23: 7 | AC23: 7 | AD23: 7 | AG23: 7
A24: Unit testing | B24: Test Phase 3 | C24: Sarah O’Toole | D24: =SUM(E24:EI24) -> 7 | AH24: 7
A25: Fixing and regression testing for minor fault | B25: Investments minor fault 3 | C25: Sarah O’Toole | D25: =SUM(E25:EI25) -> 7 | AI25: 7
A26: Integration testing | B26: Investments and Database | C26: Sarah O’Toole | D26: =SUM(E26:EI26) -> 28 | AN26: 7 | AO26: 7 | AP26: 7 | AQ26: 7
A27: Fixing and regression testing for major fault | B27: Predicted Major fault 1 | C27: Sarah O’Toole | D27: =SUM(E27:EI27) -> 14 | AR27: 7 | AU27: 7
A28: Fixing and regression testing for major fault | B28: Predicted Major fault 1 | C28: Gina Diaz | D28: =SUM(E28:EI28) -> 14 | AR28: 7 | AU28: 7
A29: Deploy Modules | B29: Deploy database and investments | C29: Terry Duran | D29: =SUM(E29:EI29) -> 14 | AR29: 7 | AU29: 7
A30: Develop Module - Data analytics | B30: Phase 1 | C30: Gina Diaz | D30: =SUM(E30:EI30) -> 35 | AV30: 7 | AW30: 7 | AX30: 7 | AY30: 7 | BB30: 7
A31: Unit testing | B31: Test Phase 1 | C31: Gina Diaz | D31: =SUM(E31:EI31) -> 7 | BC31: 7
A32: Fixing and regression testing for minor fault | B32: Analytics Minor Fault 1 | C32: Gina Diaz | D32: =SUM(E32:EI32) -> 7 | BD32: 7
A33: Develop Module - Data analytics | B33: Phase 2 | C33: Gina Diaz | D33: =SUM(E33:EI33) -> 35 | BE33: 7 | BF33: 7 | BI33: 7 | BJ33: 7 | BK33: 7
A34: Unit testing | B34: Test Phase 2 | C34: Gina Diaz | D34: =SUM(E34:EI34) -> 7 | BL34: 7
A35: Fixing and regression testing for minor fault | B35: Analytics Minor Fault 2 | C35: Gina Diaz | D35: =SUM(E35:EI35) -> 7 | BM35: 7
A36: Develop Module - Data analytics | B36: Phase 3 | C36: Gina Diaz | D36: =SUM(E36:EI36) -> 35 | BP36: 7 | BQ36: 7 | BR36: 7 | BS36: 7 | BT36: 7
A37: Unit testing | B37: Test Phase 3 | C37: Gina Diaz | D37: =SUM(E37:EI37) -> 7 | BW37: 7
A38: Fixing and regression testing for minor fault | B38: Analytics Minor Fault 3 | C38: Gina Diaz | D38: =SUM(E38:EI38) -> 7 | BX38: 7
A39: Integration testing | B39: integrate analytics | C39: Gina Diaz | D39: =SUM(E39:EI39) -> 14 | BY39: 7 | BZ39: 7
A40: Deploy Modules | B40: Deploy analytics | C40: Gina Diaz | D40: =SUM(E40:EI40) -> 7 | CA40: 7
A41: Develop Module - Information feed | B41: Phase 1 | C41: Ahad Shafiq | D41: =SUM(E41:EI41) -> 42 | AV41: 7 | AW41: 7 | AX41: 7 | AY41: 7 | BB41: 7 | BC41: 7
...

Sheet Costs
A1: Staff Costs
A2: Staff | B2: Hours worked | C2: Rate of pay | D2: Cost for project | G2: Current Income | H2: 1580900
A3: Sarah O’Toole | B3: =SUMIF(Gannt!$C$6:$C$99,Costs!A3,Gannt!$D$6:$D$101) -> 553 | C3: ='Project info summary'!G10 -> 105 | D3: =B3*C3 -> 58065 | G3: Current outgoings | H3: 985340
A4: Ahad Shafiq | B4: =SUMIF(Gannt!$C$6:$C$99,Costs!A4,Gannt!$D$6:$D$101) -> 301 | C4: ='Project info summary'!G11 -> 25 | D4: =B4*C4 -> 7525
A5: Terry Duran | B5: =SUMIF(Gannt!$C$6:$C$99,Costs!A5,Gannt!$D$6:$D$101) -> 252 | C5: ='Project info summary'!G12 -> 45 | D5: =B5*C5 -> 11340
A6: Gina Diaz | B6: =SUMIF(Gannt!$C$6:$C$99,Costs!A6,Gannt!$D$6:$D$101) -> 385 | C6: ='Project info summary'!G13 -> 47.5 | D6: =B6*C6 -> 18287.5
A7: Marius Bronski | B7: =SUMIF(Gannt!$C$6:$C$99,Costs!A7,Gannt!$D$6:$D$101) -> 28 | C7: ='Project info summary'!G14 -> 73 | D7: =B7*C7 -> 2044
A8: Project manager | B8: =(Gannt!D100/7) -> 84 | C8: 200 | D8: =B8*C8 -> 16800
A11: Project Costs | G11: Forecast With Solution
A12: Item | B12: Costs | C12: QTY | D12: Subtotal | H12: Current year | I12: After 1 year | J12: After 2 year | K12: After 3 years
A13: Software development company base fee | B13: 50000 | C13: 1 | D13: =B13*C13 -> 50000 | G13: Current Income | H13: =H2 -> 1580900 | I13: =H13*1.0875 -> 1719228.8 | J13: =I13*1.155 -> 1985709.2 | K13: =J13*1.13 -> 2243851.4
A14: Cost of training and development of internal staff | B14: 4000 | C14: 1 | D14: =B14*C14 -> 4000 | G14: Current outgoings | H14: =H3 -> 985340 | I14: =$H$3 -> 985340 | J14: =$H$3 -> 985340 | K14: =$H$3 -> 985340
A15: Cost of equipment upgrades (laptops, work stations, etc.) | B15: 15000 | C15: 1 | D15: =B15*C15 -> 15000 | G15: One-off costs | H15: =(D8+D19)-D17 -> 103000
A16: Cost of software licensing | B16: 4000 | C16: 1 | D16: =B16*C16 -> 4000 | G16: Ongoing costs | H16: =D17+B22+B23 -> 41210 | I16: =H16 -> 41210 | J16: =H16 -> 41210 | K16: =H16 -> 41210
A17: Cost of new server (cloud) | B17: 830 | C17: 12 | D17: =B17*C17 -> 9960 | G17: Total costs | H17: =H14+H15+H16 -> 1129550 | I17: =I14+I15+I16 -> 1026550 | J17: =J14+J15+J16 -> 1026550 | K17: =K14+K15+K16 -> 1026550
A18: Cost of infrastructure (networking) upgrades | B18: 13200 | C18: 1 | D18: =B18*C18 -> 13200 | G18: Profit/Loss (Inc. Carry forward) | H18: =H13-H17 -> 451350 | I18: =(I13-I17)+H18 -> 1144028.8 | J18: =(J13-J17)+I18 -> 2103188 | K18: =(K13-K17)+J18 -> 3320489.4
C19: Subtotal | D19: =SUM(D13:D18) -> 96160
A20: Ongoing costs
A22: Additional network technician | B22: 22000
A23: Maintenance costs (server, equipment, infrastructure) | B23: 9250
